<?xml version="1.0" encoding="utf-8" ?>
<!-- This URDF was automatically created by SolidWorks to URDF Exporter! Originally created by Stephen Brawner (brawner@gmail.com) 
     Commit Version: 1.6.0-4-g7f85cfe  Build Version: 1.6.7995.38578
     For more information, please see http://wiki.ros.org/sw_urdf_exporter -->
<robot name="rosbot_urdf">

    <link name="world"/>
    <joint name="base_joint" type="fixed">
	<parent link="world"/>
	<child link="base_link"/>
	<origin rpy="0 0 0" xyz="0.0 0.0 0.0"/>
    </joint>

    <link name="base_link">
        <inertial>
            <origin xyz="1.1473E-16 0.08432 6.9227E-16" rpy="0 0 0" />
            <mass value="15.751" />
            <inertia ixx="0.16005" ixy="1.1663E-16" ixz="1.0343E-16" iyy="0.22467" iyz="2.8199E-16" izz="0.16005" />
        </inertial>
        <visual>
            <origin xyz="0 0 0" rpy="0 0 0" />
            <geometry>
                <mesh filename="package://rosbot_urdf/meshes/base_link.STL" />
            </geometry>
            <material name="">
                <color rgba="0.79216 0.81961 0.93333 1" />
            </material>
        </visual>
        <collision>
            <origin xyz="0 0 0" rpy="0 0 0" />
            <geometry>
                <mesh filename="package://rosbot_urdf/meshes/base_link.STL" />
            </geometry>
        </collision>
    </link>
    <link name="link_1">
        <inertial>
            <origin xyz="-8.9882E-19 0.12615 -5.8092E-17" rpy="0 0 0" />
            <mass value="4.2774" />
            <inertia ixx="0.043593" ixy="4.1948E-18" ixz="4.6261E-09" iyy="0.026851" iyz="1.9231E-17" izz="0.031965" />
        </inertial>
        <visual>
            <origin xyz="0 0 0" rpy="0 0 0" />
            <geometry>
                <mesh filename="package://rosbot_urdf/meshes/link_1.STL" />
            </geometry>
            <material name="">
                <color rgba="0.79216 0.81961 0.93333 1" />
            </material>
        </visual>
        <collision>
            <origin xyz="0 0 0" rpy="0 0 0" />
            <geometry>
                <mesh filename="package://rosbot_urdf/meshes/link_1.STL" />
            </geometry>
        </collision>
    </link>
    <joint name="joint_1" type="revolute">
        <origin xyz="0 0 0.2" rpy="1.5708 0 -3.1416" />
        <parent link="base_link" />
        <child link="link_1" />
        <axis xyz="0 1 0" />
        <limit lower="-2.9671" upper="2.9671" effort="30" velocity="6.5" />
    </joint>
    <link name="link_2">
        <inertial>
            <origin xyz="4.0826E-05 0.20397 -4.9893E-08" rpy="0 0 0" />
            <mass value="9.2684" />
            <inertia ixx="0.21636" ixy="1.2197E-05" ixz="-3.3324E-08" iyy="0.041432" iyz="-1.0661E-07" izz="0.20763" />
        </inertial>
        <visual>
            <origin xyz="0 0 0" rpy="0 0 0" />
            <geometry>
                <mesh filename="package://rosbot_urdf/meshes/link_2.STL" />
            </geometry>
            <material name="">
                <color rgba="0.50196 0.50196 0.50196 1" />
            </material>
        </visual>
        <collision>
            <origin xyz="0 0 0" rpy="0 0 0" />
            <geometry>
                <mesh filename="package://rosbot_urdf/meshes/link_2.STL" />
            </geometry>
        </collision>
    </link>
    <joint name="joint_2" type="revolute">
        <origin xyz="0 0.205 0" rpy="0 0 0" />
        <parent link="link_1" />
        <child link="link_2" />
        <axis xyz="0 0 1" />
        <limit lower="-1.1345" upper="2.4435" effort="30" velocity="6.5" />
    </joint>
    <link name="link_3">
        <inertial>
            <origin xyz="-0.081421 0 1.6688E-16" rpy="0 0 0" />
            <mass value="2.7975" />
            <inertia ixx="0.0055105" ixy="1.2021E-18" ixz="-3.305E-18" iyy="0.020315" iyz="-7.3974E-13" izz="0.018663" />
        </inertial>
        <visual>
            <origin xyz="0 0 0" rpy="0 0 0" />
            <geometry>
                <mesh filename="package://rosbot_urdf/meshes/link_3.STL" />
            </geometry>
            <material name="">
                <color rgba="0.79216 0.81961 0.93333 1" />
            </material>
        </visual>
        <collision>
            <origin xyz="0 0 0" rpy="0 0 0" />
            <geometry>
                <mesh filename="package://rosbot_urdf/meshes/link_3.STL" />
            </geometry>
        </collision>
    </link>
    <joint name="joint_3" type="revolute">
        <origin xyz="0 0.4 0" rpy="0 0 0" />
        <parent link="link_2" />
        <child link="link_3" />
        <axis xyz="0 0 1" />
        <limit lower="-1.0472" upper="1.22173" effort="30" velocity="6.5" />
    </joint>
    <link name="link_4">
        <inertial>
            <origin xyz="-0.18964 -7.1054E-14 5.6688E-14" rpy="0 0 0" />
            <mass value="3.9492" />
            <inertia ixx="0.010077" ixy="2.2978E-14" ixz="8.8058E-12" iyy="0.050369" iyz="-1.4147E-09" izz="0.047227" />
        </inertial>
        <visual>
            <origin xyz="0 0 0" rpy="0 0 0" />
            <geometry>
                <mesh filename="package://rosbot_urdf/meshes/link_4.STL" />
            </geometry>
            <material name="">
                <color rgba="0.79216 0.81961 0.93333 1" />
            </material>
        </visual>
        <collision>
            <origin xyz="0 0 0" rpy="0 0 0" />
            <geometry>
                <mesh filename="package://rosbot_urdf/meshes/link_4.STL" />
            </geometry>
        </collision>
    </link>
    <joint name="joint_4" type="revolute">
        <origin xyz="-0.2 0 0" rpy="0 0 0" />
        <parent link="link_3" />
        <child link="link_4" />
        <axis xyz="1 0 0" />
        <limit lower="-4.7124" upper="4.7124" effort="30" velocity="6.5" />
    </joint>
    <link name="link_5">
        <inertial>
            <origin xyz="-0.049076 1.1102E-16 1.7391E-16" rpy="0 0 0" />
            <mass value="1.7741" />
            <inertia ixx="0.0023327" ixy="-3.5789E-21" ixz="-3.8632E-18" iyy="0.0083879" iyz="-1.6958E-13" izz="0.0081504" />
        </inertial>
        <visual>
            <origin xyz="0 0 0" rpy="0 0 0" />
            <geometry>
                <mesh filename="package://rosbot_urdf/meshes/link_5.STL" />
            </geometry>
            <material name="">
                <color rgba="0.79216 0.81961 0.93333 1" />
            </material>
        </visual>
        <collision>
            <origin xyz="0 0 0" rpy="0 0 0" />
            <geometry>
                <mesh filename="package://rosbot_urdf/meshes/link_5.STL" />
            </geometry>
        </collision>
    </link>
    <joint name="joint_5" type="revolute">
        <origin xyz="-0.37 0 0" rpy="0 0 1.5708" />
        <parent link="link_4" />
        <child link="link_5" />
        <axis xyz="0 0 -1" />
        <limit lower="-1.1345" upper="2.9671" effort="17" velocity="9.5" />
    </joint>
    <link name="link_6">
        <inertial>
            <origin xyz="-0.029903 0.00017669 -2.1498E-10" rpy="0 0 0" />
            <mass value="0.29255" />
            <inertia ixx="0.00040686" ixy="2.3274E-06" ixz="-7.721E-14" iyy="0.00036302" iyz="-4.0438E-12" izz="0.00044568" />
        </inertial>
        <visual>
            <origin xyz="0 0 0" rpy="0 0 0" />
            <geometry>
                <mesh filename="package://rosbot_urdf/meshes/link_6.STL" />
            </geometry>
            <material name="">
                <color rgba="0.79608 0.82353 0.93725 1" />
            </material>
        </visual>
        <collision>
            <origin xyz="0 0 0" rpy="0 0 0" />
            <geometry>
                <mesh filename="package://rosbot_urdf/meshes/link_6.STL" />
            </geometry>
        </collision>
    </link>
    <joint name="joint_6" type="revolute">
        <origin xyz="-0.168 0 0" rpy="-1.5708 0 0" />
        <parent link="link_5" />
        <child link="link_6" />
        <axis xyz="-1 0 0" />
        <limit lower="-6.1087" upper="6.1087" effort="10" velocity="17.5" />
    </joint>
    <link name="depth_camera_link">
      <inertial>
        <origin xyz="0 0 0" rpy="0 0 0"/>
        <mass value="0.1"/>
        <inertia ixx="1e-6" ixy="0.0" ixz="0.0" iyy="1e-6" iyz="0.0" izz="1e-6"/>
      </inertial>
      <visual>
        <origin xyz="0 0 0.05" rpy="0 0 0"/>
        <geometry>
          <box size="0.05 0.05 0.05"/>
        </geometry>
        <material name="blue">
          <color rgba="0.0 0.0 1.0 1.0"/>
        </material>
      </visual>
      <collision>
        <origin xyz="0 0 0.05" rpy="0 0 0"/>
        <geometry>
          <box size="0.05 0.05 0.05"/>
        </geometry>
      </collision>
    </link>

    <joint name="depth_camera_joint" type="fixed">
      <parent link="link_6"/>
      <child link="depth_camera_link"/>
      <origin xyz="0 0 0.1" rpy="0 0 0"/>
    </joint>

    <!-- GAZEBO SENSOR PLUGIN -->
    <gazebo reference="depth_camera_link">
      <sensor name="depth_camera_sensor" type="depth">
        <always_on>true</always_on>
        <update_rate>30</update_rate>
        <visualize>true</visualize>
        <camera>
          <horizontal_fov>1.047</horizontal_fov>
          <image>
            <width>640</width>
            <height>480</height>
            <format>R8G8B8</format>
          </image>
          <clip>
            <near>0.05</near>
            <far>5.0</far>
          </clip>
        </camera>
        <plugin name="depth_camera_controller" filename="libgazebo_ros_camera.so">
          <cameraName>depth_camera</cameraName>
          <always_on>true</always_on>
          <update_rate>30.0</update_rate>
          <frameName>depth_camera_link</frameName>
          <image_topic_name>image_raw</image_topic_name>
          <depth_image_topic_name>depth/image_raw</depth_image_topic_name>
          <camera_info_topic_name>camera_info</camera_info_topic_name>
          <robot_namespace>/depth_camera</robot_namespace>
        </plugin>
      </sensor>
    </gazebo>
    <transmission name="trans_joint_1">
        <type>transmission_interface/SimpleTransmission</type>
        <joint name="joint_1">
            <hardwareInterface>hardware_interface/PositionJointInterface</hardwareInterface>
        </joint>
        <actuator name="joint_1_motor">
            <hardwareInterface>hardware_interface/PositionJointInterface</hardwareInterface>
            <mechanicalReduction>1</mechanicalReduction>
        </actuator>
    </transmission>
    <transmission name="trans_joint_2">
        <type>transmission_interface/SimpleTransmission</type>
        <joint name="joint_2">
            <hardwareInterface>hardware_interface/PositionJointInterface</hardwareInterface>
        </joint>
        <actuator name="joint_2_motor">
            <hardwareInterface>hardware_interface/PositionJointInterface</hardwareInterface>
            <mechanicalReduction>1</mechanicalReduction>
        </actuator>
    </transmission>
    <transmission name="trans_joint_3">
        <type>transmission_interface/SimpleTransmission</type>
        <joint name="joint_3">
            <hardwareInterface>hardware_interface/PositionJointInterface</hardwareInterface>
        </joint>
        <actuator name="joint_3_motor">
            <hardwareInterface>hardware_interface/PositionJointInterface</hardwareInterface>
            <mechanicalReduction>1</mechanicalReduction>
        </actuator>
    </transmission>
    <transmission name="trans_joint_4">
        <type>transmission_interface/SimpleTransmission</type>
        <joint name="joint_4">
            <hardwareInterface>hardware_interface/PositionJointInterface</hardwareInterface>
        </joint>
        <actuator name="joint_4_motor">
            <hardwareInterface>hardware_interface/PositionJointInterface</hardwareInterface>
            <mechanicalReduction>1</mechanicalReduction>
        </actuator>
    </transmission>
    <transmission name="trans_joint_5">
        <type>transmission_interface/SimpleTransmission</type>
        <joint name="joint_5">
            <hardwareInterface>hardware_interface/PositionJointInterface</hardwareInterface>
        </joint>
        <actuator name="joint_5_motor">
            <hardwareInterface>hardware_interface/PositionJointInterface</hardwareInterface>
            <mechanicalReduction>1</mechanicalReduction>
        </actuator>
    </transmission>
    <transmission name="trans_joint_6">
        <type>transmission_interface/SimpleTransmission</type>
        <joint name="joint_6">
            <hardwareInterface>hardware_interface/PositionJointInterface</hardwareInterface>
        </joint>
        <actuator name="joint_6_motor">
            <hardwareInterface>hardware_interface/PositionJointInterface</hardwareInterface>
            <mechanicalReduction>1</mechanicalReduction>
        </actuator>
    </transmission>
    <gazebo>
        <plugin name="gazebo_ros_control" filename="libgazebo_ros_control.so">
            <robotNamespace>/</robotNamespace>
        </plugin>
    </gazebo>
</robot>
