<?xml version="1.0" encoding="utf-8" ?>
<!-- This URDF was automatically created by SolidWorks to URDF Exporter! Originally created by Stephen Brawner (brawner@gmail.com) 
     Commit Version: 1.6.0-4-g7f85cfe  Build Version: 1.6.7995.38578
     For more information, please see http://wiki.ros.org/sw_urdf_exporter -->
<robot name="aravind_urdf">
    <link name="world" />
    <link name="base_link">
        <inertial>
            <origin xyz="-0.00444542379406162 -0.00728259656011918 0.150855715391748" rpy="0 0 0" />
            <mass value="0.0776" />
            <inertia ixx="0.682994384050526" ixy="-0.00176176483111433" ixz="-1.3496431751147E-06" iyy="0.569207104597129" iyz="-6.7059329204648E-05" izz="0.726934894228407" />
        </inertial>
        <visual>
            <origin xyz="0 0 0" rpy="0 0 0" />
            <geometry>
                <mesh filename="package://arduinobot_description/meshess/base_link.STL" />
            </geometry>
            <material name="black">
                <color rgba="0.1 0.1 0.1 1" />
            </material>
        </visual>
        <collision>
            <origin xyz="0 0 0" rpy="0 0 0" />
            <geometry>
                <mesh filename="package://arduinobot_description/meshess/base_link.STL" />
            </geometry>
        </collision>
    </link>
    <joint name="virtual_joint" type="fixed">
        <parent link="world" />
        <child link="base_link" />
        <origin xyz="0 0 0" rpy="0 0 0" />
    </joint>
    <link name="link1">
        <inertial>
            <origin xyz="0.0119892929601358 -1.17419403382344E-05 0.165030366968437" rpy="0 0 0" />
            <mass value="0.0595" />
            <inertia ixx="0.253744656389447" ixy="-1.42217680188873E-05" ixz="-0.0482130899952277" iyy="0.32634982848464" iyz="-1.97738577848718E-05" izz="0.274271591295868" />
        </inertial>
        <visual>
            <origin xyz="0 0 0" rpy="0 0 0" />
            <geometry>
                <mesh filename="package://arduinobot_description/meshess/link1.STL" />
            </geometry>
            <material name="red">
                <color rgba="0.2 0.3 0.8 1" />
            </material>
        </visual>
        <collision>
            <origin xyz="0 0 0" rpy="0 0 0" />
            <geometry>
                <mesh filename="package://arduinobot_description/meshess/link1.STL" />
            </geometry>
        </collision>
    </link>
    <joint name="joint1" type="continuous">
        <origin xyz="-0.0069915 -0.0049824 0.4275" rpy="0 0 0" />
        <parent link="base_link" />
        <child link="link1" />
        <axis xyz="0 0 1" />
    </joint>
    <link name="link2">
        <inertial>
            <origin xyz="-0.000127547684951041 -0.191907585751342 -0.0487051171492652" rpy="0 0 0" />
            <mass value="0.0851" />
            <inertia ixx="1.23520650072034" ixy="-0.000335695202028227" ixz="9.87452864807071E-08" iyy="0.743952310820634" iyz="-2.02395137328158E-05" izz="1.92183897433748" />
        </inertial>
        <visual>
            <origin xyz="0 0 0" rpy="0 0 0" />
            <geometry>
                <mesh filename="package://arduinobot_description/meshess/link2.STL" />
            </geometry>
            <material name="black">
                <color rgba="0.7 0.6 0.1 1" />
            </material>
        </visual>
        <collision>
            <origin xyz="0 0 0" rpy="0 0 0" />
            <geometry>
                <mesh filename="package://arduinobot_description/meshess/link2.STL" />
            </geometry>
        </collision>
    </link>
    <joint name="joint2" type="continuous">
        <origin xyz="0.21279 -1.6792E-05 0.212" rpy="1.5708 0 -1.5708" />
        <parent link="link1" />
        <child link="link2" />
        <axis xyz="0 0 -1" />
    </joint>
    <link name="link3">
        <inertial>
            <origin xyz="-0.00166338636581466 -0.110913891042808 0.0324420515741239" rpy="0 0 0" />
            <mass value="0.0498" />
            <inertia ixx="0.145911390485181" ixy="3.42426002611999E-05" ixz="3.03387992579821E-06" iyy="0.205974101669925" iyz="-0.000397722963446423" izz="0.325097638091713" />
        </inertial>
        <visual>
            <origin xyz="0 0 0" rpy="0 0 0" />
            <geometry>
                <mesh filename="package://arduinobot_description/meshess/link3.STL" />
            </geometry>
            <material name="red">
                <color rgba="0.8 0.2 0.2 1" />
            </material>
        </visual>
        <collision>
            <origin xyz="0 0 0" rpy="0 0 0" />
            <geometry>
                <mesh filename="package://arduinobot_description/meshess/link3.STL" />
            </geometry>
        </collision>
    </link>
    <joint name="joint3" type="continuous">
        <origin xyz="0 0.512 0.083" rpy="0 0 0" />
        <parent link="link2" />
        <child link="link3" />
        <axis xyz="0 0 -1" />
    </joint>
    <link name="link4">
        <inertial>
            <origin xyz="-0.000155760312209952 0.0174731282922833 0.137141744648845" rpy="0 0 0" />
            <mass value="0.0106" />
            <inertia ixx="0.0588768825579607" ixy="-1.60894019269219E-05" ixz="4.09378613988868E-05" iyy="0.0586634562117962" iyz="-0.000952461734697792" izz="0.0141089996724949" />
        </inertial>
        <visual>
            <origin xyz="0 0 0" rpy="0 0 0" />
            <geometry>
                <mesh filename="package://arduinobot_description/meshess/link4.STL" />
            </geometry>
            <material name="black">
                <color rgba="0.752941176470588 0.752941176470588 0.752941176470588 1" />
            </material>
        </visual>
        <collision>
            <origin xyz="0 0 0" rpy="0 0 0" />
            <geometry>
                <mesh filename="package://arduinobot_description/meshess/link4.STL" />
            </geometry>
        </collision>
    </link>
    <joint name="joint4" type="continuous">
        <origin xyz="0 0.14775 0.087" rpy="1.5708 0 3.1416" />
        <parent link="link3" />
        <child link="link4" />
        <axis xyz="0 0 1" />
    </joint>
    <link name="link5">
        <inertial>
            <origin xyz="-0.00147733703375156 -1.17160596451171E-05 0.05681353828552" rpy="0 0 0" />
            <mass value="0.0039" />
            <inertia ixx="0.00289363858140416" ixy="-4.15842530537375E-07" ixz="-0.000212534336821572" iyy="0.0059720834734646" iyz="-1.15304151445946E-06" izz="0.00596449267447299" />
        </inertial>
        <visual>
            <origin xyz="0 0 0" rpy="0 0 0" />
            <geometry>
                <mesh filename="package://arduinobot_description/meshess/link5.STL" />
            </geometry>
            <material name="gray">
                <color rgba="0.7 0.7 0.7 1" />
            </material>
        </visual>
        <collision>
            <origin xyz="0 0 0" rpy="0 0 0" />
            <geometry>
                <mesh filename="package://arduinobot_description/meshess/link5.STL" />
            </geometry>
        </collision>
    </link>
    <joint name="joint5" type="continuous">
        <origin xyz="-0.00011158 0.021335 0.44" rpy="1.5708 0 0" />
        <parent link="link4" />
        <child link="link5" />
        <axis xyz="0 0 -1" />
    </joint>
    <link name="link6">
        <inertial>
            <origin xyz="5.4244208818055E-05 -3.36060310970887E-06 0.0177180164917108" rpy="0 0 0" />
            <mass value="0.00064" />
            <inertia ixx="0.000342396263703602" ixy="3.04371433957007E-06" ixz="2.84087050971312E-07" iyy="0.000354827800235625" iyz="-2.2167618705053E-08" izz="0.00062989775719375" />
        </inertial>
        <visual>
            <origin xyz="0 0 0" rpy="0 0 0" />
            <geometry>
                <mesh filename="package://arduinobot_description/meshess/link6.STL" />
            </geometry>
            <material name="red">
                <color rgba="0.529411764705882 0.549019607843137 0.549019607843137 1" />
            </material>
        </visual>
        <collision>
            <origin xyz="0 0 0" rpy="0 0 0" />
            <geometry>
                <mesh filename="package://arduinobot_description/meshess/link6.STL" />
            </geometry>
        </collision>
    </link>
    <joint name="joint6" type="continuous">
        <origin xyz="0.067 0 0.072" rpy="1.5708 0 1.5708" />
        <parent link="link5" />
        <child link="link6" />
        <axis xyz="0 0 1" />
    </joint>
    <!-- gazebo color-->
    <gazebo reference="base_link">
        <material>Gazebo/Gray</material>
        <plugin name="gazebo_ros_control">
            <robotNamespace>/</robotNamespace>
        </plugin>
    </gazebo>
    <gazebo reference="link1">
        <material>Gazebo/Orange</material>
    </gazebo>
    <gazebo reference="link2">
        <material>Gazebo/Gray</material>
    </gazebo>
    <gazebo reference="link3">
        <material>Gazebo/Orange</material>
    </gazebo>
    <gazebo reference="link4">
        <material>Gazebo/Gray</material>
    </gazebo>
    <gazebo reference="link5">
        <material>Gazebo/Orange</material>
    </gazebo>
    <gazebo reference="link6">
        <material>Gazebo/Blue</material>
    </gazebo>
    <!--Position Transmissions-->
    <transmission name="t_1">
        <type>transmission_interface/SimpleTransmission</type>
        <joint name="joint1">
            <hardwareInterface>hardware_interface/PositionJointInterface</hardwareInterface>
        </joint>
        <actuator name="motor_1">
            <hardwareInterface>hardware_interface/PositionJointInterface</hardwareInterface>
            <mechanicalReduction>1</mechanicalReduction>
        </actuator>
    </transmission>
    <transmission name="t_2">
        <type>transmission_interface/SimpleTransmission</type>
        <joint name="joint2">
            <hardwareInterface>hardware_interface/PositionJointInterface</hardwareInterface>
        </joint>
        <actuator name="motor_2">
            <hardwareInterface>hardware_interface/PositionJointInterface</hardwareInterface>
            <mechanicalReduction>1</mechanicalReduction>
        </actuator>
    </transmission>
    <transmission name="t_3">
        <type>transmission_interface/SimpleTransmission</type>
        <joint name="joint3">
            <hardwareInterface>hardware_interface/PositionJointInterface</hardwareInterface>
        </joint>
        <actuator name="motor_3">
            <hardwareInterface>hardware_interface/PositionJointInterface</hardwareInterface>
            <mechanicalReduction>1</mechanicalReduction>
        </actuator>
    </transmission>
    <transmission name="t_4">
        <type>transmission_interface/SimpleTransmission</type>
        <joint name="joint4">
            <hardwareInterface>hardware_interface/PositionJointInterface</hardwareInterface>
        </joint>
        <actuator name="motor_4">
            <hardwareInterface>hardware_interface/PositionJointInterface</hardwareInterface>
            <mechanicalReduction>1</mechanicalReduction>
        </actuator>
    </transmission>
    <transmission name="t_5">
        <type>transmission_interface/SimpleTransmission</type>
        <joint name="joint5">
            <hardwareInterface>hardware_interface/PositionJointInterface</hardwareInterface>
        </joint>
        <actuator name="motor_5">
            <hardwareInterface>hardware_interface/PositionJointInterface</hardwareInterface>
            <mechanicalReduction>1</mechanicalReduction>
        </actuator>
    </transmission>
    <transmission name="t_6">
        <type>transmission_interface/SimpleTransmission</type>
        <joint name="joint6">
            <hardwareInterface>hardware_interface/PositionJointInterface</hardwareInterface>
        </joint>
        <actuator name="motor_6">
            <hardwareInterface>hardware_interface/PositionJointInterface</hardwareInterface>
            <mechanicalReduction>1</mechanicalReduction>
        </actuator>
    </transmission>
    <!-- Plugin-->
    <gazebo>
        <plugin name="gazebo_ros_control" filename="libgazebo_ros_control.so" />
        <robotNamespace>/arduinobot</robotNamespace>
        <robotSimType>gazebo_ros_control/DefaultRobotHWSim</robotSimType>
        <legacyModeNS>true</legacyModeNS>
    </gazebo>
    <!-- self collide -->
    <!-- <gazebo reference="link1">
    <selfCollide>true</selfCollide>
  </gazebo>
  <gazebo reference="link2">
    <selfCollide>true</selfCollide>
  </gazebo>
  <gazebo reference="link3">
    <selfCollide>true</selfCollide>
  </gazebo>
  <gazebo reference="link4">
    <selfCollide>true</selfCollide>
  </gazebo>
  <gazebo reference="link5">
    <selfCollide>true</selfCollide>
  </gazebo>
  <gazebo reference="link6">
    <selfCollide>true</selfCollide>
  </gazebo>  -->
</robot>