<?xml version="1.0" encoding="utf-8"?>
<!-- This URDF was automatically created by SolidWorks to URDF Exporter! Originally created by Stephen Brawner (brawner@gmail.com) 
     Commit Version: 1.6.0-4-g7f85cfe  Build Version: 1.6.7995.38578
     For more information, please see http://wiki.ros.org/sw_urdf_exporter -->
<robot
  name="three_dof">
  <link name="world" />
  <link
    name="base_link">
    <inertial>
      <origin
        xyz="-0.00431825502539671 -0.00566373488320885 0.323272983577505"
        rpy="0 0 0" />
      <mass
        value="79.6654029695768" />
      <inertia
        ixx="0.573355253302005"
        ixy="0.0017561395261876"
        ixz="6.95230375143639E-05"
        iyy="0.687136996298016"
        iyz="-9.66176789904465E-07"
        izz="0.735241435441936" />
    </inertial>
    <visual>
      <origin
        xyz="0 0 0"
        rpy="0 0 0" />
      <geometry>
        <mesh
          filename="package://arduinobot_description/meshes/base_link.STL" />
      </geometry>
      <material
        name="black">
        <color
          rgba="0.1 0.1 0.1 1" />
      </material>
    </visual>
    <collision>
      <origin
        xyz="0 0 0"
        rpy="0 0 0" />
      <geometry>
        <mesh
          filename="package://arduinobot_description/meshes/base_link.STL" />
      </geometry>
    </collision>
  </link>
      <joint name="virtual_joint" type="fixed">
        <parent link="world" />
        <child link="base_link" />
        <origin xyz="0 0 0" rpy="0 0 0" />
    </joint>
  <link
    name="link1">
    <inertial>
      <origin
        xyz="8.42513902520742E-06 0.0434262949156984 0.170114473981018"
        rpy="0 0 0" />
      <mass
        value="40.7059478899697" />
      <inertia
        ixx="0.274475922205371"
        ixy="1.82077498242031E-05"
        ixz="1.96447102595056E-05"
        iyy="0.22628292831378"
        iyz="-0.0482139507692608"
        izz="0.215894409124819" />
    </inertial>
    <visual>
      <origin
        xyz="0 0 0"
        rpy="0 0 0" />
      <geometry>
        <mesh
          filename="package://arduinobot_description/meshes/link1.STL" />
      </geometry>
      <material
        name="blue">
        <color
          rgba="0.2 0.2 0.7 1" />
      </material>
    </visual>
    <collision>
      <origin
        xyz="0 0 0"
        rpy="0 0 0" />
      <geometry>
        <mesh
          filename="package://arduinobot_description/meshes/link1.STL" />
      </geometry>
    </collision>
  </link>
  <joint
    name="joint1"
    type="continuous">
    <origin
      xyz="-0.0065346 -0.0081621 0.59003"
      rpy="0 0 1.5708" />
    <parent
      link="base_link" />
    <child
      link="link1" />
    <axis
      xyz="0 0 1" />
  </joint>
  <link
    name="link2">
    <inertial>
      <origin
        xyz="-0.000127533996189498 -0.191909527477922 -0.26149236779315"
        rpy="0 0 0" />
      <mass
        value="10.9233639477083" />
      <inertia
        ixx="0.158360782590535"
        ixy="-4.30378464138589E-05"
        ixz="1.26596522120862E-08"
        iyy="0.0953794761931371"
        iyz="-2.59480945319534E-06"
        izz="0.246389636037909" />
    </inertial>
    <visual>
      <origin
        xyz="0 0 0"
        rpy="0 0 0" />
      <geometry>
        <mesh
          filename="package://arduinobot_description/meshes/link2.STL" />
      </geometry>
      <material
        name="black">
        <color
          rgba="0.1 0.1 0.1 1" />
      </material>
    </visual>
    <collision>
      <origin
        xyz="0 0 0"
        rpy="0 0 0" />
      <geometry>
        <mesh
          filename="package://arduinobot_description/meshes/link2.STL" />
      </geometry>
    </collision>
  </link>
  <joint
    name="joint2"
    type="continuous">
    <origin
      xyz="1.6792E-05 0 0.212"
      rpy="1.5708 0 0" />
    <parent
      link="link1" />
    <child
      link="link2" />
    <axis
      xyz="0 0 -1" />
  </joint>
  <link
    name="link3">
    <inertial>
      <origin
        xyz="-0.0228313878912571 -3.73527074088997E-05 -0.132032896237542"
        rpy="0 0 0" />
      <mass
        value="17.3454951445915" />
      <inertia
        ixx="0.0317675300356897"
        ixy="1.43517256169409E-05"
        ixz="0.000399562777711981"
        iyy="0.0322430934777024"
        iyz="3.04510784441626E-06"
        izz="0.0457582904028881" />
    </inertial>
    <visual>
      <origin
        xyz="0 0 0"
        rpy="0 0 0" />
      <geometry>
        <mesh
          filename="package://arduinobot_description/meshes/link3.STL" />
      </geometry>
      <material
        name="blue">
        <color
          rgba="0.2 0.2 0.7 1" />
      </material>
    </visual>
    <collision>
      <origin
        xyz="0 0 0"
        rpy="0 0 0" />
      <geometry>
        <mesh
          filename="package://arduinobot_description/meshes/link3.STL" />
      </geometry>
    </collision>
  </link>
  <joint
    name="joint3"
    type="continuous">
    <origin
      xyz="0 0.512 0"
      rpy="0 0 0" />
    <parent
      link="link2" />
    <child
      link="link3" />
    <axis
      xyz="0 0 -1" />
  </joint>
  <link
    name="link4">
    <inertial>
      <origin
        xyz="1.38777878078145E-16 0 0.075"
        rpy="0 0 0" />
      <mass
        value="0.0265071880146639" />
      <inertia
        ixx="5.0073734858951E-05"
        ixy="2.68833699080117E-23"
        ixz="-9.72260894308173E-20"
        iyy="5.0073734858951E-05"
        iyz="1.65157223027251E-20"
        izz="7.45514662912422E-07" />
    </inertial>
    <visual>
      <origin
        xyz="0 0 0"
        rpy="0 0 0" />
      <geometry>
        <mesh
          filename="package://arduinobot_description/meshes/link4.STL" />
      </geometry>
      <material
        name="red">
        <color
          rgba="0.7 0.2 0.2 1" />
      </material>
    </visual>
    <collision>
      <origin
        xyz="0 0 0"
        rpy="0 0 0" />
      <geometry>
        <mesh
          filename="package://arduinobot_description/meshes/link4.STL" />
      </geometry>
    </collision>
  </link>
  <joint
    name="joint4"
    type="continuous">
    <origin
      xyz="0.1105 -0.0041121 -0.14479"
      rpy="0 1.5708 0" />
    <parent
      link="link3" />
    <child
      link="link4" />
    <axis
      xyz="0 0 -1" />
  </joint>

    <!-- gazebo color-->
  <gazebo reference="base_link">
        <material>Gazebo/Gray</material>
        <plugin name="gazebo_ros_control">
            <robotNamespace>/</robotNamespace>
        </plugin>
  </gazebo>
  <gazebo reference="link1">
      <material>Gazebo/Orange</material>
  </gazebo>
  <gazebo reference="link2">
      <material>Gazebo/Gray</material>
  </gazebo>
  <gazebo reference="link3">
      <material>Gazebo/Orange</material>
  </gazebo>
  <gazebo reference="link4">
      <material>Gazebo/Gray</material>
  </gazebo>

  <!--Position Transmissions-->
  <transmission name="t_1">
        <type>transmission_interface/SimpleTransmission</type>
        <joint name="joint1">
            <hardwareInterface>hardware_interface/PositionJointInterface</hardwareInterface>
        </joint>
        <actuator name="motor_1">
            <hardwareInterface>hardware_interface/PositionJointInterface</hardwareInterface>
            <mechanicalReduction>1</mechanicalReduction>
        </actuator>
  </transmission>
  <transmission name="t_2">
        <type>transmission_interface/SimpleTransmission</type>
        <joint name="joint2">
            <hardwareInterface>hardware_interface/PositionJointInterface</hardwareInterface>
        </joint>
        <actuator name="motor_2">
            <hardwareInterface>hardware_interface/PositionJointInterface</hardwareInterface>
            <mechanicalReduction>1</mechanicalReduction>
        </actuator>
  </transmission>
  <transmission name="t_3">
        <type>transmission_interface/SimpleTransmission</type>
        <joint name="joint3">
            <hardwareInterface>hardware_interface/PositionJointInterface</hardwareInterface>
        </joint>
        <actuator name="motor_3">
            <hardwareInterface>hardware_interface/PositionJointInterface</hardwareInterface>
            <mechanicalReduction>1</mechanicalReduction>
        </actuator>
  </transmission>
  <transmission name="t_4">
        <type>transmission_interface/SimpleTransmission</type>
        <joint name="joint4">
            <hardwareInterface>hardware_interface/PositionJointInterface</hardwareInterface>
        </joint>
        <actuator name="motor_4">
            <hardwareInterface>hardware_interface/PositionJointInterface</hardwareInterface>
            <mechanicalReduction>1</mechanicalReduction>
        </actuator>
  </transmission>
  <gazebo>
      <plugin name="gazebo_ros_control" filename="libgazebo_ros_control.so" />
      <robotNamespace>/arduinobot</robotNamespace>
      <robotSimType>gazebo_ros_control/DefaultRobotHWSim</robotSimType>
      <legacyModeNS>true</legacyModeNS>
  </gazebo>
</robot>